<?xml version="1.0"?>
<robot name="serial_robot_5axis">
     <link name="world"/>

     <link name="first_link">
            <visual>
              <geometry>
                 
                  <box size="0.05 0.05 0.5"/>

              </geometry>
                <material name="silver">
                  <color rgba="0.75 0.75 0.75 1"/>
              </material>
              <origin rpy="0 0 0" xyz="0 0 0.25"/>
           </visual>
           
           <collision>
              <geometry>
                    <box size="0.05 0.05 0.5"/>
              </geometry>
    
             <origin rpy="0 0 0" xyz="0 0 0.25"/>
          </collision>
          
          <inertial>
                  <mass value="1.0"/>
                  <origin rpy="0 0 0" xyz="0 0 0.025"/>
                  <inertia ixx="0.11" iyy="0.11" izz="0.005" ixy="0.0" ixz="0.01" iyz="0.01"/>
          </inertial>

          
    </link>
    <joint name="joint0" type="fixed">
       
       <parent link="world"/>
       <child link="first_link"/>
       <origin rpy="0 0 0" xyz="0.0 0.0 0.05"/>
    </joint>
    

    <link name="second_link">
            <visual>
              <geometry>
                  <cylinder length="0.4" radius="0.05"/>
              </geometry>
                <material name="silver"/>
                <origin rpy="0 0 0" xyz="0.04 0.03 0.2"/>
           </visual>

           <collision>
              <geometry>
                    <cylinder length="0.4" radius="0.05"/>
              </geometry>
    
             <origin rpy="0 0 0" xyz="0.04 0.03 0.2"/>
          </collision>
          
          <inertial>
                  <mass value="1.0"/>
                  <origin rpy="0 0 0" xyz="0 0 0.025"/>
                  <inertia ixx="0.04" iyy="0.04" izz="0.002" ixy="0" ixz="0" iyz="0"/>
          </inertial>

    </link>
    <joint name="p_joint" type="prismatic">
       <parent link="first_link"/>
       <child link="second_link"/>
       <origin rpy="0 1.5708 0" xyz="0.0 -0.1 0.45"/>
       <axis xyz="1 0 0" />
        <limit effort="1000.0" lower="-0.03" upper="0.30" velocity="0.5"/>
    </joint>


   <link name="third_link">
            <visual>
              <geometry>
                  <cylinder length="0.4" radius="0.05"/>
              </geometry>
                <material name="silver"/>
                <origin rpy="0 0 0" xyz="0 0 0.2"/>
           </visual>

           
           <collision>
              <geometry>
                    <cylinder length="0.4" radius="0.05"/>
              </geometry>
    
              <origin rpy="0 0 0" xyz="0 0 0.2"/>
          </collision>
          
          <inertial>
                  <mass value="1.0"/>
                  <origin rpy="0 0 0" xyz="0 0 0.025"/>
                  <inertia ixx="0.04" iyy="0.04" izz="0.002" ixy="0" ixz="0" iyz="0"/>
          </inertial>
    </link>
    <joint name="R_joint1" type="continuous">
       <axis xyz="1 0 0"/>
       <parent link="second_link"/>
       <child link="third_link"/>
       <origin rpy="0 0 0" xyz="-0.05 0.0 0.35"/>
    </joint>

    
      <link name="fourth_link">
            <visual>
              <geometry>
                  <cylinder length="0.4" radius="0.05"/>
              </geometry>
                <material name="silver"/>
                <origin rpy="0 0 0" xyz="0 0 0.2"/>
           </visual>

           <collision>
              <geometry>
                    <cylinder length="0.4" radius="0.05"/>
              </geometry>
    
              <origin rpy="0 0 0" xyz="0 0 0.2"/>
          </collision>
          
          <inertial>
                  <mass value="1.0"/>
                  <origin rpy="0 0 0" xyz="0 0 0.025"/>
                 <inertia ixx="0.04" iyy="0.04" izz="0.002" ixy="0" ixz="0" iyz="0"/>
          </inertial>
    </link>
    <joint name="R_joint2" type="continuous">
       <axis xyz="0 0 1"/>
       <parent link="third_link"/>
       <child link="fourth_link"/>
       <origin rpy="0 0 0" xyz="-0.1 0.0 0.35"/>
    </joint>
   

      <link name="fifth_link">
            <visual>
              <geometry>
                  <cylinder length="0.4" radius="0.05"/>
              </geometry>
                <material name="silver"/>
                <origin rpy="0 0 0" xyz="0 0 0.2"/>
           </visual>

           <collision>
              <geometry>
                    <cylinder length="0.4" radius="0.05"/>
              </geometry>
    
              <origin rpy="0 0 0" xyz="0 0 0.2"/>
          </collision>
          
          <inertial>
                  <mass value="1.0"/>
                  <origin rpy="0 0 0" xyz="0 0 0.025"/>
                  <inertia ixx="0.04" iyy="0.04" izz="0.002" ixy="0" ixz="0" iyz="0"/>
          </inertial>
    </link>
    <joint name="R_joint3" type="continuous">
       <axis xyz="1 0 0"/>
       <parent link="fourth_link"/>
       <child link="fifth_link"/>
       <origin rpy="0 0 0" xyz="-0.10 0.0 0.35"/>
    </joint>
    
     <link name="sixth_link">
            <visual>
              <geometry>
                  <cylinder length="0.4" radius="0.05"/>
              </geometry>
                <material name="silver"/>
                <origin rpy="0 0 0" xyz="0 0 0.2"/>
           </visual>

           <collision>
              <geometry>
                    <cylinder length="0.4" radius="0.05"/>
              </geometry>
    
              <origin rpy="0 0 0" xyz="0 0 0.2"/>
          </collision>
          
          <inertial>
                  <mass value="1.0"/>
                  <origin rpy="0 0 0" xyz="0 0 0.025"/>
                  <inertia ixx="0.04" iyy="0.04" izz="0.002" ixy="0" ixz="0" iyz="0"/>
          </inertial>
    </link>
    <joint name="R_joint4" type="continuous">
       <axis xyz="1 0 0"/>
       <parent link="fifth_link"/>
       <child link="sixth_link"/>
       <origin rpy="0 0 0" xyz="-0.10 0.0 0.35"/>
    </joint>

    

   <link name="gripper">
            <visual>
              <geometry>
                  <box size="0.1 0.2 0.1"/>
              </geometry>
                <material name="silver"/>
                <origin rpy="0 0 0" xyz="0 0 0"/>
            </visual>
   

    <collision>
              <geometry>
                    <box size="0.1 0.2 0.1"/>
              </geometry>
    
               <origin rpy="0 0 0" xyz="0 0 0"/>
          </collision>
          
          <inertial>
                  <mass value="1.0"/>
                  <origin rpy="0 0 0" xyz="0 0 0.025"/>
                  <inertia ixx="0.03" iyy="0.03" izz="0.01" ixy="0.01" ixz="0.01" iyz="0.01"/>
          </inertial>
     </link>

     <joint name="gripper_joint" type="continuous">
       <axis xyz="0 1 0"/>
       <parent link="sixth_link"/>
       <child link="gripper"/>
       <origin rpy="0 0 0" xyz="0.0 -0.15 0.35"/>
    </joint>
    
     <transmission name="tran0">
	<type>transmission_interface/SimpleTransmission</type>
	<joint name="p_joint">
	<hardwareInterface>PositionJointInterface</hardwareInterface>
	</joint>
	<actuator name="motor0">
	<hardwareInterface>PositionJointInterface</hardwareInterface>
	<mechanicalReduction>1</mechanicalReduction>
	</actuator>
     </transmission>

     <transmission name="tran1">
	<type>transmission_interface/SimpleTransmission</type>
	<joint name="R_joint1">
	<hardwareInterface>PositionJointInterface</hardwareInterface>
	</joint>
	<actuator name="motor1">
	<hardwareInterface>PositionJointInterface</hardwareInterface>
	<mechanicalReduction>1</mechanicalReduction>
	</actuator>
     </transmission>

     <transmission name="tran2">
	<type>transmission_interface/SimpleTransmission</type>
	<joint name="R_joint2">
	<hardwareInterface>PositionJointInterface</hardwareInterface>
	</joint>
	<actuator name="motor2">
	<hardwareInterface>PositionJointInterface</hardwareInterface>
	<mechanicalReduction>1</mechanicalReduction>
	</actuator>
     </transmission>
    
     <transmission name="tran3">
	<type>transmission_interface/SimpleTransmission</type>
	<joint name="R_joint3">
	<hardwareInterface>PositionJointInterface</hardwareInterface>
	</joint>
	<actuator name="motor3">
	<hardwareInterface>PositionJointInterface</hardwareInterface>
	<mechanicalReduction>1</mechanicalReduction>
	</actuator>
     </transmission>

     <transmission name="tran4">
	<type>transmission_interface/SimpleTransmission</type>
	<joint name="R_joint4">
	<hardwareInterface>PositionJointInterface</hardwareInterface>
	</joint>
	<actuator name="motor4">
	<hardwareInterface>PositionJointInterface</hardwareInterface>
	<mechanicalReduction>1</mechanicalReduction>
	</actuator>
     </transmission>
      
     <transmission name="tran5">
	<type>transmission_interface/SimpleTransmission</type>
	<joint name="gripper_joint">
	<hardwareInterface>PositionJointInterface</hardwareInterface>
	</joint>
	<actuator name="motor5">
	<hardwareInterface>PositionJointInterface</hardwareInterface>
	<mechanicalReduction>1</mechanicalReduction>
	</actuator>
     </transmission>
     

      <gazebo>
	<plugin name="control" filename="libgazebo_ros_control.so"/>
	<plugin name="joint_state_publisher" filename="libgazebo_ros_joint_state_publisher.so">
	<jointName>p_joint,R_joint1,R_joint2,R_joint3,R_joint4,gripper_joint</jointName>
	</plugin>
      </gazebo>

   
</robot>

